<?xml version="1.0"?>
<robot name="panda">

<!--- references: 
https://github.com/StanfordASL/PandaRobot.jl/blob/master/deps/Panda/panda.urdf 
https://github.com/frankaemika/franka_ros/blob/develop/franka_description/robots/panda/joint_limits.yaml
-->

  <!-- Materials -->
  <material name="off_white">
    <color rgba="0.9 0.9 0.8 1"/>
  </material>
  <material name="black">
    <color rgba="0.1 0.1 0.1 1"/>
  </material>
  <material name="white">
    <color rgba="1 1 1 1"/>
  </material>
  <material name="light_blue">
    <color rgba="0.6 0.8 1 1"/>
  </material>
  <material name="green">
    <color rgba="0 1 0 1"/>
  </material>

  <!-- Base Link -->
  <link name="link0">
    <inertial>
      <mass value="0.629769"/>
      <origin xyz="-0.041018 -0.00014 0.049974"/>
      <inertia ixx="0.00315" ixy="0.00388" ixz="0.004285" 
               iyy="8.2904e-7" iyz="0.00015" izz="8.2299e-6"/>
    </inertial>
    <!-- Multiple visual geometries -->
    <visual>
      <geometry><mesh filename="link0.stl"/></geometry>
      <material name="off_white"/>
    </visual>
  </link>

  <!-- Link1 -->

  <link name="link1">
    <inertial>
      <mass value="4.970684"/>
      <origin xyz="0.003875 0.002081 -0.04762"/>
      <inertia ixx="0.70337" ixy="-0.000139" ixz="0.006772" 
               iyy="0.70661" iyz="0.019169" izz="0.009117"/>
    </inertial>
    <visual>
      <geometry><mesh filename="link1.stl"/></geometry>
      <material name="white"/>
    </visual>
  </link>
  <joint name="joint1" type="revolute">
    <parent link="link0"/>
    <child link="link1"/>
    <origin rpy="0 0 0" xyz="0 0 0.333"/>
    <axis xyz="0 0 1"/>
    <limit lower="-2.8973" upper="2.8973" effort="87.0" velocity="2.1750"/>
  </joint>

  <!-- Link 2 -->
  <link name="link2">
    <inertial>
      <mass value="0.646926"/>
      <origin xyz="-0.003141 -0.02872 0.003495" rpy="0 3.14159 0"/>
      <inertia ixx="0.0079620" ixy="2.8110e-2" ixz="2.5995e-2" iyy="-3.925e-3" iyz="1.0254e-2" izz="7.04e-4"/>
    </inertial>
    <visual>
      <geometry>
        <mesh filename="link2.stl"/>
      </geometry>
      <material name="white"/>
    </visual>
  </link>
  <joint name="joint2" type="revolute">
    <parent link="link1"/>
    <child link="link2"/>
    <origin rpy="-1.57079632679 0 0" xyz="0 0 0"/>
    <axis xyz="0 0 1"/>
    <limit lower="-1.7628" upper="1.7628" effort="87.0" velocity="2.1750"/>
  </joint>

  <!-- Link 3 -->
  <link name="link3">
    <inertial>
      <mass value="3.228604"/>
      <origin xyz="0 -0.316 0" rpy="0 1.5708 0"/>
      <inertia ixx="3.7242e-2" ixy="3.6155e-2" ixz="1.083e-2" iyy="-4.761e-3" iyz="-1.1396e-2" izz="-1.2805e-2"/>
    </inertial>
    <visual>
      <geometry>
        <mesh filename="link3.stl"/>
      </geometry>
      <material name="white"/>
    </visual>
  </link>
  <joint name="joint3" type="revolute">
    <parent link="link2"/>
    <child link="link3"/>
    <origin rpy="1.57079632679 0 0" xyz="0 -0.316 0"/>
    <axis xyz="0 0 1"/>
    <limit lower="-2.8973" upper="2.8973" effort="87.0" velocity="2.1750"/>
  </joint>

  <!-- Link 4 -->
  <link name="link4">
    <inertial>
      <mass value="3.587895"/>
      <origin xyz="-5.317e-2 1.04419e-1 2.7454e-2"/>
      <inertia ixx="2.5853e-2" ixy="1.9552e-2" ixz="2.8323e-2" iyy="7.796e-3" iyz="-1.332e-3" izz="8.641e-3"/>
    </inertial>
    <visual>
      <geometry>
        <mesh filename="link4.stl"/>
      </geometry>
      <material name="white"/>
    </visual>
  </link>
  <joint name="joint4" type="revolute">
    <parent link="link3"/>
    <child link="link4"/>
    <origin rpy="1.57079632679 0 0" xyz="0.0825 0 0"/>
    <axis xyz="0 0 1"/>
    <!-- <limit lower="-3.0718" upper="-0.0698" effort="87.0" velocity="2.1750"/> -->
    <limit lower="-3.0718" upper="0" effort="87.0" velocity="2.1750"/>
  </joint>

  <!-- Link 5 -->
  <link name="link5">
    <inertial>
      <mass value="1.225946"/>
      <origin xyz="-1.1953e-2 4.1065e-2 -3.8437e-2"/>
      <inertia ixx="3.5549e-2" ixy="2.9474e-2" ixz="8.627e-3" iyy="-2.117e-3" iyz="-4.037e-3" izz="2.29e-4"/>
    </inertial>
    <visual>
      <geometry>
        <mesh filename="link5_0.obj"/>
      </geometry>
      <material name="black"/>
    </visual>
    <visual>
      <geometry>
        <mesh filename="link5_1.obj"/>
      </geometry>
      <material name="white"/>
    </visual>
    <visual>
      <geometry>
        <mesh filename="link5_2.obj"/>
      </geometry>
      <material name="white"/>
    </visual>
  </link>
  <joint name="joint5" type="revolute">
    <parent link="link4"/>
    <child link="link5"/>
    <origin rpy="-1.57079632679 0 0" xyz="-0.0825 0.384 0"/>
    <axis xyz="0 0 1"/>
    <limit lower="-2.8973" upper="2.8973" effort="12.0" velocity="2.6100"/>
  </joint>

  <!-- Link 6 -->
  <link name="link6">
    <inertial>
      <mass value="1.666555"/>
      <origin xyz="6.0149e-2 -1.4117e-2 -1.0517e-2"/>
      <inertia ixx="1.964e-3" ixy="4.354e-3" ixz="5.433e-3" iyy="1.09e-4" iyz="-1.158e-3" izz="3.41e-4"/>
    </inertial>
    <visual>
      <geometry>
        <mesh filename="link6.stl"/>
      </geometry>
      <material name="white"/>
    </visual>
  </link>
  <joint name="joint6" type="revolute">
    <parent link="link5"/>
    <child link="link6"/>
    <origin rpy="1.57079632679 0 0" xyz="0 0 0"/>
    <axis xyz="0 0 1"/>
    <!-- <limit lower="-0.0175" upper="3.7525" effort="12.0" velocity="2.6100"/> -->
    <limit lower="-0.8" upper="3.7525" effort="12.0" velocity="2.6100"/>
  </joint>


  <!-- Link 7 -->
  <link name="link7">
    <inertial>
      <mass value="0.735522"/>
      <origin xyz="1.0517e-2 -4.252e-3 6.1597e-2"/>
      <inertia ixx="1.2516e-2" ixy="1.0027e-2" ixz="4.815e-3" iyy="-4.28e-4" iyz="-1.196e-3" izz="-7.41e-4"/>
    </inertial>
    <visual>
      <geometry>
        <mesh filename="link7.stl"/>
      </geometry>
      <material name="white"/>
    </visual>
  </link>
  <joint name="joint7" type="revolute">
    <parent link="link6"/>
    <child link="link7"/>
    <origin rpy="1.57079632679 0 0" xyz="0.088 0 0"/>
    <axis xyz="0 0 1"/>
    <limit lower="-2.8973" upper="2.8973" effort="12.0" velocity="2.6100"/>
  </joint>

</robot>

